<?xml version="1.0"?>

<robot
    xmlns:sensor="http://playerstage.sourceforge.net/gazebo/xmlschema/#sensor"
    xmlns:controller="http://playerstage.sourceforge.net/gazebo/xmlschema/#controller"
    xmlns:interface="http://playerstage.sourceforge.net/gazebo/xmlschema/#interface"
          xmlns:xacro="http://playerstage.sourceforge.net/gazebo/xmlschema/#interface">
  
  
  
    <xacro:property name="diff_z_offset" value="-0.055" />
    <xacro:property name="wheel_radius" value="0.12" />
    <xacro:property name="wheel_dist_x" value="0.3" />

    <xacro:macro name="tracker_diff_drive_macro">	
    
    <joint name="wheel_left_front_joint" type="continuous">
      <parent link="base_link"/>
      <child link="wheel_left_front_link"/>
      <origin xyz="${wheel_dist_x} ${flipper_offset_y} ${wheel_radius+diff_z_offset}" rpy="${-M_PI/2} 0 0"/>
      <axis xyz="0 0 1"/>
    </joint>
    <link name="wheel_left_front_link">
      <visual>
        <geometry>
          <cylinder length="0.0206" radius="${wheel_radius}"/>
        </geometry>
        <origin xyz="0 0 0" rpy="0 0 0"/>
      </visual>
      <collision>
        <geometry>
          <cylinder length="0.0206" radius="${wheel_radius}"/>
        </geometry>
        <origin rpy="0 0 0" xyz="0 0 0"/>
      </collision>
      <inertial>
        <mass value="0.01" />
        <origin xyz="0 0 0" />
        <inertia ixx="0.001" ixy="0.0" ixz="0.0"
                 iyy="0.001" iyz="0.0" 
                 izz="0.001" />
      </inertial>
    </link>
    
    <joint name="wheel_right_front_joint" type="continuous">
      <parent link="base_link"/>
      <child link="wheel_right_front_link"/>
      <origin xyz="${wheel_dist_x} ${-flipper_offset_y} ${wheel_radius+diff_z_offset}" rpy="${-M_PI/2} 0 0"/>
      <axis xyz="0 0 1"/>
    </joint>
    <link name="wheel_right_front_link">
      <visual>
        <geometry>
          <cylinder length="0.0206" radius="${wheel_radius}"/>
        </geometry>
        <origin xyz="0 0 0" rpy="0 0 0"/>
      </visual>
      <collision>
        <geometry>
          <cylinder length="0.0206" radius="${wheel_radius}"/>
        </geometry>
        <origin rpy="0 0 0" xyz="0 0 0"/>
      </collision>
      <inertial>
        <mass value="0.01" />
        <origin xyz="0 0 0" />
        <inertia ixx="0.001" ixy="0.0" ixz="0.0"
                 iyy="0.001" iyz="0.0" 
                 izz="0.001" />
      </inertial>
    </link>
    

    <joint name="wheel_left_rear_joint" type="continuous">
      <parent link="base_link"/>
      <child link="wheel_left_rear_link"/>
      <origin xyz="-${wheel_dist_x} ${flipper_offset_y} ${wheel_radius+diff_z_offset}" rpy="${-M_PI/2} 0 0"/>
      <axis xyz="0 0 1"/>
    </joint>
    <link name="wheel_left_rear_link">
      <visual>
        <geometry>
          <cylinder length="0.0206" radius="${wheel_radius}"/>
        </geometry>
        <origin xyz="0 0 0" rpy="0 0 0"/>
      </visual>
      <collision>
        <geometry>
          <cylinder length="0.0206" radius="${wheel_radius}"/>
        </geometry>
        <origin rpy="0 0 0" xyz="0 0 0"/>
      </collision>
      <inertial>
        <mass value="0.01" />
        <origin xyz="0 0 0" />
        <inertia ixx="0.001" ixy="0.0" ixz="0.0"
                 iyy="0.001" iyz="0.0" 
                 izz="0.001" />
      </inertial>
    </link>
    
    <joint name="wheel_right_rear_joint" type="continuous">
      <parent link="base_link"/>
      <child link="wheel_right_rear_link"/>
      <origin xyz="-${wheel_dist_x} ${-flipper_offset_y} ${wheel_radius+diff_z_offset}" rpy="${-M_PI/2} 0 0"/>
      <axis xyz="0 0 1"/>
    </joint>
    <link name="wheel_right_rear_link">
      <visual>
        <geometry>
          <cylinder length="0.0206" radius="${wheel_radius}"/>
        </geometry>
        <origin xyz="0 0 0" rpy="0 0 0"/>
      </visual>
      <collision>
        <geometry>
          <cylinder length="0.0206" radius="${wheel_radius}"/>
        </geometry>
        <origin rpy="0 0 0" xyz="0 0 0"/>
      </collision>
      <inertial>
        <mass value="0.01" />
        <origin xyz="0 0 0" />
        <inertia ixx="0.001" ixy="0.0" ixz="0.0"
                 iyy="0.001" iyz="0.0" 
                 izz="0.001" />
      </inertial>
    </link>
    

    	  <gazebo reference="wheel_left_front_link">
	    <mu1>1.0</mu1>
	    <mu2>1.0</mu2>
	    <kp>1000000.0</kp>
	    <kd>100.0</kd>
	    <minDepth>0.001</minDepth>
	    <maxVel>1.0</maxVel>
	  </gazebo>
	
	  <gazebo reference="wheel_right_front_link">
	    <mu1>1.0</mu1>
	    <mu2>1.0</mu2>
	    <kp>1000000.0</kp>
	    <kd>100.0</kd>
	    <minDepth>0.001</minDepth>
	    <maxVel>1.0</maxVel>
	  </gazebo>

    	  <gazebo reference="wheel_left_rear_link">
	    <mu1>1.0</mu1>
	    <mu2>1.0</mu2>
	    <kp>1000000.0</kp>
	    <kd>100.0</kd>
	    <minDepth>0.001</minDepth>
	    <maxVel>1.0</maxVel>
	  </gazebo>
	
	  <gazebo reference="wheel_right_rear_link">
	    <mu1>1.0</mu1>
	    <mu2>1.0</mu2>
	    <kp>1000000.0</kp>
	    <kd>100.0</kd>
	    <minDepth>0.001</minDepth>
	    <maxVel>1.0</maxVel>
	  </gazebo>

  <gazebo>
    <plugin name="diffdrive_plugin_multiwheel" filename="libdiffdrive_plugin_multi_wheel.so">                
      <alwaysOn>true</alwaysOn>
      <updateRate>10.0</updateRate>
      <leftJoints>wheel_left_front_joint wheel_left_rear_joint</leftJoints>
      <rightJoints>wheel_right_front_joint wheel_right_rear_joint</rightJoints>
      <wheelSeparation>${flipper_offset_y*2}</wheelSeparation>
      <wheelDiameter>${wheel_radius*2}</wheelDiameter>
      <torque>50000</torque>      
      <robotNamespace>/</robotNamespace>
      <robotBaseFrame>base_link</robotBaseFrame>
      <commandTopic>/cmd_vel_raw</commandTopic>
      <publishOdometryTf>0</publishOdometryTf>
      <publishOdometryMsg>1</publishOdometryMsg>
    </plugin>
  </gazebo>

</xacro:macro> 
    

    
</robot>
